Workbook
Name Slicer_Année: #N/A
Name Slicer_Indicateur: #N/A

Sheet Raw Data
A1: Item | B1: 2024 (K.TND) | C1: 2023 (K.TND)
A2: ETAT DE RESULTAT
A3: Intérêts et revenus assimilés | B3: 665998 | C3: 602209
A4: Commissions (produits) | B4: 90516 | C4: 86197
A5: Gains sur portefeuille commercial | B5: 22521 | C5: 24181
A6: Revenus portefeuille investissement | B6: 103952 | C6: 102211
A7: Total produits exploitation | B7: 882987 | C7: 814798
A8: Intérêts et charges assimilées | B8: 359938 | C8: 327255
A9: Commissions (charges) | B9: 13064 | C9: 9593
A10: Total charges exploitation | B10: 373002 | C10: 336848
A11: Produit Net Bancaire (PNB) | B11: 509985 | C11: 477950
A12: Dotations provisions sur créances | B12: 33109 | C12: 58852
A13: Dotations provisions portefeuille | B13: 6733 | C13: 10974
A14: Autres produits exploitation | B14: 1526 | C14: 1476
... A23: Résultat net de lexercice | B23: 188415 | C23: 170327
A25: BILAN
A26: Caisse et avoirs BCT | B26: 665692 | C26: 193171
A27: Créances établissements bancaires | B27: 536026 | C27: 452275
A28: Créances sur la clientèle | B28: 6067260 | C28: 5827707
A29: Portefeuille investissement | B29: 1243775 | C29: 1126683
A30: Valeurs immobilisées | B30: 94297 | C30: 75114
A31: Autres actifs | B31: 31791 | C31: 43571
A32: Total Actifs | B32: 8638841 | C32: 7718521
A33: Banque Centrale et CCP | B33: 0 | C33: 117130
A34: Dépôts établissements bancaires | B34: 50675 | C34: 61460
A35: Dépôts de la clientèle | B35: 6695428 | C35: 5803572
A36: Emprunts et ressources spéciales | B36: 181024 | C36: 257291
A37: Autres passifs | B37: 300289 | C37: 177758
... A44: Total Passifs + Capitaux Propres | B44: 8638841 | C44: 7718521

Sheet Clean Data
A1: Banque de Tunisie — Analyse Financière 2024
A2: Source: Rapport Annuel BT 2024 | Unité: Milliers de Dinars Tunisiens (K.TND)
A4: ETAT DE RESULTAT | B4: 2024 (K.TND) | C4: 2023 (K.TND) | D4: Variation YoY
A5: Intérêts et revenus assimilés | B5: 665998 | C5: 602209 | D5: =(B5-C5)/C5 -> 0.10592502
A6: Commissions (produits) | B6: 90516 | C6: 86197 | D6: =(B6-C6)/C6 -> 0.050106152
A7: Gains sur portefeuille commercial | B7: 22521 | C7: 24181 | D7: =(B7-C7)/C7 -> -0.068648939
A8: Revenus portefeuille investissement | B8: 103952 | C8: 102211 | D8: =(B8-C8)/C8 -> 0.017033392
A9: Total produits exploitation | B9: =SUM(B5:B8) -> 882987 | C9: =SUM(C5:C8) -> 814798 | D9: =(B9-C9)/C9 -> 0.083688227
A10: Intérêts et charges assimilées | B10: 359938 | C10: 327255 | D10: =(B10-C10)/C10 -> 0.099870132
A11: Commissions (charges) | B11: 13064 | C11: 9593 | D11: =(B11-C11)/C11 -> 0.36182633
A12: Total charges exploitation | B12: =SUM(B10:B11) -> 373002 | C12: =SUM(C10:C11) -> 336848 | D12: =(B12-C12)/C12 -> 0.10733031
A13: Produit Net Bancaire (PNB) | B13: =B9-B12 -> 509985 | C13: =C9-C12 -> 477950 | D13: =(B13-C13)/C13 -> 0.06702584
A14: Dotations provisions sur créances | B14: 33109 | C14: 58852 | D14: =(B14-C14)/C14 -> -0.43741929
A15: Dotations provisions portefeuille | B15: 6733 | C15: 10974 | D15: =(B15-C15)/C15 -> -0.3864589
A16: Autres produits exploitation | B16: 1526 | C16: 1476 | D16: =(B16-C16)/C16 -> 0.033875339
A17: Frais de personnel | B17: 110758 | C17: 102455 | D17: =(B17-C17)/C17 -> 0.081040457
A18: Charges générales exploitation | B18: 45219 | C18: 42816 | D18: =(B18-C18)/C18 -> 0.056123879
A19: Dotations aux amortissements | B19: 8808 | C19: 7960 | D19: =(B19-C19)/C19 -> 0.10653266
A20: Résultat exploitation | B20: =B13-B14-B15+B16-B17-B18-B19 -> 306884 | C20: =C13-C14-C15+C16-C17-C18-C19 -> 256369 | D20: =(B20-C20)/C20 -> 0.1970402
A21: Eléments ordinaires (solde) | B21: -38 | C21: 1833 | D21: -
A22: Impôt sur les bénéfices | B22: 108613 | C22: 79748 | D22: =(B22-C22)/C22 -> 0.36195265
A23: Résultat net activités ordinaires | B23: =B20+B21-B22 -> 198233 | C23: =C20+C21-C22 -> 178454 | D23: =(B23-C23)/C23 -> 0.11083529
A24: Eléments extraordinaires (solde) | B24: -9818 | C24: -8127 | D24: =(B24-C24)/C24 -> 0.20807186
A25: Résultat net de lexercice | B25: =B23+B24 -> 188415 | C25: =C23+C24 -> 170327 | D25: =(B25-C25)/C25 -> 0.10619573
A27: BILAN | B27: 2024 (K.TND) | C27: 2023 (K.TND) | D27: Variation YoY
A28: Actifs
A29: Caisse et avoirs BCT | B29: 665692 | C29: 193171 | D29: =(B29-C29)/C29 -> 2.446128
A30: Créances établissements bancaires | B30: 536026 | C30: 452275 | D30: =(B30-C30)/C30 -> 0.18517716
A31: Créances sur la clientèle | B31: 6067260 | C31: 5827707 | D31: =(B31-C31)/C31 -> 0.041105876
A32: Portefeuille investissement | B32: 1243775 | C32: 1126683 | D32: =(B32-C32)/C32 -> 0.1039263
A33: Valeurs immobilisées | B33: 94297 | C33: 75114 | D33: =(B33-C33)/C33 -> 0.25538515
A34: Autres actifs | B34: 31791 | C34: 43571 | D34: =(B34-C34)/C34 -> -0.27036332
A35: Total Actifs | B35: =SUM(B29:B34) -> 8638841 | C35: =SUM(C29:C34) -> 7718521 | D35: =(B35-C35)/C35 -> 0.11923528
A36: Passifs
A37: Banque Centrale et CCP | B37: 0 | C37: 117130 | D37: =(B37-C37)/C37 -> -1
A38: Dépôts établissements bancaires | B38: 50675 | C38: 61460 | D38: =(B38-C38)/C38 -> -0.17547999
A39: Dépôts de la clientèle | B39: 6695428 | C39: 5803572 | D39: =(B39-C39)/C39 -> 0.15367363
A40: Emprunts et ressources spéciales | B40: 181024 | C40: 257291 | D40: =(B40-C40)/C40 -> -0.29642312
A41: Autres passifs | B41: 300289 | C41: 177758 | D41: =(B41-C41)/C41 -> 0.68931356
A42: Total Passifs | B42: =SUM(B37:B41) -> 7227416 | C42: =SUM(C37:C41) -> 6417211 | D42: =(B42-C42)/C42 -> 0.126255
...

Sheet Analyse des Ratios
A1: Banque de Tunisie — Analyse des Ratios Financiers
A2: Ratios calculés sur base des états financiers 2024 vs 2023
A4: RATIOS DE RENTABILITÉ | B4: 2024 | C4: 2023 | D4: Interprétation
A5: Marge Nette (Net Profit Margin) | B5: ='Clean Data'!B25/'Clean Data'!B9 -> 0.21338366 | C5: ='Clean Data'!C25/'Clean Data'!C9 -> 0.209042 | D5: 21,3% en 2024 vs 20,9% en 2023 , En amélioration. La banque conserve 21 centimes de profit pour chaque dinar de produits. Signe de bonnemaîtrise des charges.
A6: Retour sur Actifs (ROA) | B6: ='Clean Data'!B25/'Clean Data'!B35 -> 0.021810217 | C6: ='Clean Data'!C25/'Clean Data'!C35 -> 0.022067311 | D6: 2,2% stable en 2024 et 2023 , Chaque dinar d'actif génère 2,2 centimes de profit net. Ratio solide pour une banque tunisienne.
A7: Retour sur Capitaux Propres (ROE) | B7: ='Clean Data'!B25/'Clean Data'!B48 -> 0.13349275 | C7: ='Clean Data'!C25/'Clean Data'!C48 -> 0.13088887 | D7: 13,3% en 2024 vs 13,1% en 2023 , En légère hausse. Pour chaque 100 TND investi par les actionnaires, la banque génère 13,3 TND de profit. Très bon rendement.
A8: Coefficient d'exploitation | B8: =('Clean Data'!B17+'Clean Data'!B18+'Clean Data'!B19)/'Clean Data'!B13 -> 0.32311735 | C8: =('Clean Data'!C17+'Clean Data'!C18+'Clean Data'!C19)/'Clean Data'!C13 -> 0.32060048 | D8: 32,3% en 2024 vs 32,1% en 2023 , Excellent. Bien en dessous du seuil de 60%. La banque est très efficace opérationnellement , seulement 32 centimes de charges pour chaque dinar de PNB.
A10: RATIOS DE SOLVABILITÉ | B10: 2024 | C10: 2023 | D10: Interprétation
A11: Ratio Dettes / Capitaux Propres | B11: ='Clean Data'!B42/'Clean Data'!B48 -> 5.1206518 | C11: ='Clean Data'!C42/'Clean Data'!C48 -> 4.9313469 | D11: 5,12x en 2024 vs 4,93x en 2023 , Légère hausse du levier. Normal pour une banque. Signifie que pour 1 TND de capitaux propres, la banque porte 5,12 TND de dettes.
A12: Ratio de Solvabilité | B12: ='Clean Data'!B48/'Clean Data'!B35 -> 0.16338129 | C12: ='Clean Data'!C48/'Clean Data'!C35 -> 0.16859577 | D12: 16,3% en 2024 vs 16,9% en 2023 , Légère baisse mais reste solide. 16,3% des actifs sont financés par fonds propres. Bonne protection contre les risques.
A14: RATIOS BANCAIRES SPÉCIFIQUES | B14: 2024 | C14: 2023 | D14: Interprétation
A15: Ratio Crédits / Dépôts | B15: ='Clean Data'!B31/'Clean Data'!B39 -> 0.90617956 | C15: ='Clean Data'!C31/'Clean Data'!C39 -> 1.0041586 | D15: 90,6% en 2024 vs 100,4% en 2023 , Amélioration significative. En 2023 la banque prêtait plus qu'elle ne collectait (risque). En 2024 elle est revenue dans la zone cible de 70-90%. Très positif.
A16: Marge d'Intérêt Nette (NIM) | B16: =('Clean Data'!B5-'Clean Data'!B10)/'Clean Data'!B35 -> 0.035428364 | C16: =('Clean Data'!C5-'Clean Data'!C10)/'Clean Data'!C35 -> 0.035622628 | D16: 3,5% en 2024 vs 3,6% en 2023 , Légère compression. La marge entre ce que la banque gagne sur les prêts et ce qu'elle paie sur les dépôts se réduit légèrement. À surveiller.
A18: RATIO SUPPLÉMENTAIRE — QUALITÉ DES ACTIFS | B18: 2024 | C18: 2023 | D18: Interprétation
A19: Coût du Risque | B19: ='Clean Data'!B14/'Clean Data'!B31 -> 0.0054569938 | C19: ='Clean Data'!C14/'Clean Data'!C31 -> 0.010098655 | D19: Baisse de 0,5% vs 1,0% en 2023 , La qualité du portefeuille de crédit s'est nettement améliorée
A20: Variation des Provisions | B20: =('Clean Data'!B14-'Clean Data'!C14)/'Clean Data'!C14 -> -0.43741929 | C20: - | D20: Provisions réduites de -43,7% , principal moteur de la hausse du Résultat d'exploitation (+19,7%)

Sheet Analyse des tendences 
A1: Banque de Tunisie — Analyse des Tendances 2023 vs 2024
A2: Evolution des indicateurs financiers clés — en K.TND
A4: Indicateur | B4: 2024 (K.TND) | C4: 2023 (K.TND) | D4: Variation (K.TND) | E4: Croissance %
A5: Total Produits d'exploitation | B5: ='Clean Data'!B9 -> 882987 | C5: ='Clean Data'!C9 -> 814798 | D5: =B5-C5 -> 68189 | E5: =(B5-C5)/C5 -> 0.083688227
A6: Produit Net Bancaire (PNB) | B6: ='Clean Data'!B13 -> 509985 | C6: ='Clean Data'!C13 -> 477950 | D6: =B6-C6 -> 32035 | E6: =(B6-C6)/C6 -> 0.06702584
A7: Résultat d'exploitation | B7: ='Clean Data'!B20 -> 306884 | C7: ='Clean Data'!C20 -> 256369 | D7: =B7-C7 -> 50515 | E7: =(B7-C7)/C7 -> 0.1970402
A8: Résultat Net de l'exercice | B8: ='Clean Data'!B25 -> 188415 | C8: ='Clean Data'!C25 -> 170327 | D8: =B8-C8 -> 18088 | E8: =(B8-C8)/C8 -> 0.10619573
A9: Total Actifs | B9: ='Clean Data'!B35 -> 8638841 | C9: ='Clean Data'!C35 -> 7718521 | D9: =B9-C9 -> 920320 | E9: =(B9-C9)/C9 -> 0.11923528
A10: Dépôts de la clientèle | B10: ='Clean Data'!B39 -> 6695428 | C10: ='Clean Data'!C39 -> 5803572 | D10: =B10-C10 -> 891856 | E10: =(B10-C10)/C10 -> 0.15367363
A11: Créances sur la clientèle | B11: ='Clean Data'!B31 -> 6067260 | C11: ='Clean Data'!C31 -> 5827707 | D11: =B11-C11 -> 239553 | E11: =(B11-C11)/C11 -> 0.041105876
A12: Total Capitaux Propres | B12: ='Clean Data'!B48 -> 1411425 | C12: ='Clean Data'!C48 -> 1301310 | D12: =B12-C12 -> 110115 | E12: =(B12-C12)/C12 -> 0.084618577
A14: CONCLUSIONS CLÉS
A15: ✅ Le Résultat Net a progressé de +10,6% passant de 170 327 à 188 415 K.TND
A16: ✅ Le Total Actifs a crû de +11,9% ,expansion significative du bilan
A17: ✅ Les Dépôts clientèle ont augmenté de +15,4% ,forte confiance des clients
A18: ✅ Le PNB a progressé de +6,7% , solidité du coeur du métier bancaire
A19: ⚠️Les Créances clientèle ont crû de +4,1% , croissance modérée des prêts
A20: ⚠️Les Capitaux Propres ont augmenté de +8,5% , renforcement du capital

Sheet Résumé exécutif
B1: BANQUE DE TUNISIE — TABLEAU DE BORD FINANCIER 2024
B2: Analyse des performances financières | Source: Rapport Annuel 2024
B4: INDICATEURS CLÉS DE PERFORMANCE
B5: Total Actifs (K.TND) | C5: ='Clean Data'!B35 -> 8638841 | E5: Résultat Net (K.TND) | F5: ='Clean Data'!B25 -> 188415
B6: Croissance vs 2023 | C6: =('Clean Data'!B35-'Clean Data'!C35)/'Clean Data'!C35 -> 0.11923528 | E6: Croissance vs 2023 | F6: =('Clean Data'!B25-'Clean Data'!C25)/'Clean Data'!C25 -> 0.10619573
B8: Produit Net Bancaire (K.TND) | C8: ='Clean Data'!B13 -> 509985 | E8: Dépôts de la clientèle (K.TND) | F8: ='Clean Data'!B39 -> 6695428
B9: Croissance vs 2023 | C9: =('Clean Data'!B13-'Clean Data'!C13)/'Clean Data'!C13 -> 0.06702584 | E9: Croissance vs 2023 | F9: =('Clean Data'!B39-'Clean Data'!C39)/'Clean Data'!C39 -> 0.15367363
B11: SYNTHÈSE DES RATIOS
B12: Ratio | C12: 2024 | E12: Ratio | F12: 2024
B13: Marge Nette | C13: ='Analyse des Ratios'!B5 -> 0.21338366 | E13: ROE | F13: ='Analyse des Ratios'!B7 -> 0.13349275
B14: ROA | C14: ='Analyse des Ratios'!B6 -> 0.021810217 | E14: Ratio Crédits/Dépôts | F14: ='Analyse des Ratios'!B15 -> 0.90617956
B15: Coefficient d'exploitation | C15: ='Analyse des Ratios'!B8 -> 0.32311735 | E15: NIM | F15: ='Analyse des Ratios'!B16 -> 0.035428364
B16: Ratio Dettes/CP | C16: ='Analyse des Ratios'!B11 -> 5.1206518 | E16: Ratio Solvabilité | F16: ='Analyse des Ratios'!B12 -> 0.16338129
B18: CONCLUSIONS DE L'ANALYSTE
B19: ✅ Rentabilité en hausse , ROE 13,3% et Marge Nette 21,3% démontrent une banque profitable
B20: ✅ Efficacité opérationnelle excellente , Coefficient d'exploitation 32,3% bien sous le seuil de 60%
B21: ✅ Forte croissance des dépôts +15,4% , signal de confiance élevée de la clientèle
B22: ✅ Bilan solide , Total Actifs en hausse de +11,9% à 8,6 milliards K.TND
B23: ⚠️ NIM en légère compression 3,5% vs 3,6% , pression sur les marges d'intérêt à surveiller
B24: ⚠️ Levier financier élevé 5,12x , normal pour une banque mais nécessite un suivi

Sheet Pivot_Source
A1: Année | B1: Indicateur | C1: Valeur
A2: 2024 | B2: Total Produits | C2: ='Clean Data'!B9 -> 882987
A3: 2023 | B3: Total Produits | C3: ='Clean Data'!C9 -> 814798
A4: 2024 | B4: PNB | C4: ='Clean Data'!B13 -> 509985
A5: 2023 | B5: PNB | C5: ='Clean Data'!C13 -> 477950
A6: 2024 | B6: Résultat Exploitation | C6: ='Clean Data'!B20 -> 306884
A7: 2023 | B7: Résultat Exploitation | C7: ='Clean Data'!C20 -> 256369
A8: 2024 | B8: Résultat Net | C8: ='Clean Data'!B25 -> 188415
A9: 2023 | B9: Résultat Net | C9: ='Clean Data'!C25 -> 170327
A10: 2024 | B10: Total Actifs | C10: ='Clean Data'!B35 -> 8638841
A11: 2023 | B11: Total Actifs | C11: ='Clean Data'!C35 -> 7718521
A12: 2024 | B12: Dépôts Clientèle | C12: ='Clean Data'!B39 -> 6695428
A13: 2023 | B13: Dépôts Clientèle | C13: ='Clean Data'!C39 -> 5803572
A14: 2024 | B14: Créances Clientèle | C14: ='Clean Data'!B31 -> 6067260
A15: 2023 | B15: Créances Clientèle | C15: ='Clean Data'!C31 -> 5827707
A16: 2024 | B16: Capitaux Propres | C16: ='Clean Data'!B48 -> 1411425
A17: 2023 | B17: Capitaux Propres | C17: ='Clean Data'!C48 -> 1301310
A19: Etape | B19: valeur
A20: Total Produits | B20: ='Clean Data'!B9 -> 882987
A21: Charges exploitation | B21: =-'Clean Data'!B12 -> -373002
A22: PNB | B22: ='Clean Data'!B13 -> 509985
A23: Provisions | B23: =-'Clean Data'!B14 -> -33109
A24: Frais Personnel | B24: =-'Clean Data'!B17 -> -110758
A25: Charges Générales | B25: =-'Clean Data'!B18 -> -45219
A26: Amortissements | B26: =-'Clean Data'!B19 -> -8808
A27: Autres produits | B27: ='Clean Data'!B16 -> 1526
A28: Résultat Exploitation | B28: ='Clean Data'!B20 -> 306884
A29: Impôts | B29: =-'Clean Data'!B22 -> -108613
A30: Eléments Extraord. | B30: ='Clean Data'!B24 -> -9818
A31: Résultat Net | B31: ='Clean Data'!B25 -> 188415
A33: ratio | B33: 2024 | C33: 2023
A34: Marge Nette % | B34: ='Analyse des Ratios'!B5 -> 0.21338366 | C34: ='Analyse des Ratios'!C5 -> 0.209042
A35: ROA % | B35: ='Analyse des Ratios'!B6 -> 0.021810217 | C35: ='Analyse des Ratios'!C6 -> 0.022067311
A36: ROE % | B36: ='Analyse des Ratios'!B7 -> 0.13349275 | C36: ='Analyse des Ratios'!C7 -> 0.13088887
A37: Coefficient d'exploitation | B37: ='Analyse des Ratios'!B8 -> 0.32311735 | C37: ='Analyse des Ratios'!C8 -> 0.32060048
A38: NIM % | B38: ='Analyse des Ratios'!B16 -> 0.035428364 | C38: ='Analyse des Ratios'!C16 -> 0.035622628
A39: Solvabilité % | B39: ='Analyse des Ratios'!B12 -> 0.16338129 | C39: ='Analyse des Ratios'!C12 -> 0.16859577

Sheet Pivot_Table
A3: Sum of Valeur | B3: Column Labels
A4: Row Labels | B4: 2023 | C4: 2024 | D4: Grand Total
A5: Capitaux Propres | B5: 1301310 | C5: 1411425 | D5: 2712735
A6: Créances Clientèle | B6: 5827707 | C6: 6067260 | D6: 11894967
A7: Dépôts Clientèle | B7: 5803572 | C7: 6695428 | D7: 12499000
A8: PNB | B8: 477950 | C8: 509985 | D8: 987935
A9: Résultat Exploitation | B9: 256369 | C9: 306884 | D9: 563253
A10: Résultat Net | B10: 170327 | C10: 188415 | D10: 358742
A11: Total Actifs | B11: 7718521 | C11: 8638841 | D11: 16357362
A12: Total Produits | B12: 814798 | C12: 882987 | D12: 1697785
A13: Grand Total | B13: 22370554 | C13: 24701225 | D13: 47071779

Sheet Dashboard
A1: BANQUE DE TUNISIE — TABLEAU DE BORD INTERACTIF
A19: ANALYSE DE LA PERFORMANCE | Q19: COMPARAISON DES RATIOS
A39: Source: Rapport Annuel Banque de Tunisie 2024 | Analyse: Karim Hammemi | Outil: Microsoft Excel
